Workbook

Sheet Test Plan
A1: Test Plan & Execution Record
A2: SauceDemo E-Commerce | Manual Functional Testing
A4: DOCUMENT CONTROL
A5: Document Title | B5: SauceDemo E-Commerce — Test Plan & Execution Record
A6: Prepared By | B6: Anusha Yadav
A7: Date | B7: 46293
A8: Version | B8: 1.0
A9: Status | B9: Executed
A11: 1. OBJECTIVE
A12: Purpose | B12: Verify that the core shopping flow of Sauce Demo — Login, Product Listing/Sort, Cart and Checkout — works as expected, and record every deviation as a defect with evidence.
A14: 2. SCOPE
A15: In scope | B15: • Login (valid, invalid, empty fields, locked-out user, password masking) • Product Listing and Sorting • Cart (add, remove, persistence, continue shopping, checkout with empty cart) • Checkout (information form validation, order overview totals, order completion, cancel) • Exploratory testing with the 'problem_user' account
A16: Out of scope | B16: • Performance, security and accessibility testing • Cross-browser and mobile testing (executed on Chrome only) • Automation testing • Burger menu (About, Logout, Reset App State), footer links and product detail pages • Accounts 'performance_glitch_user', 'error_user' and 'visual_user'
A18: 3. TEST APPROACH
A19: Type | B19: Manual, black-box functional testing
A20: Techniques | B20: Positive and negative testing, input validation checks, error guessing and exploratory testing
A21: Method | B21: Expected results were defined from the documented behaviour of the application. Each test case was then executed in a live browser and the actual result and status were recorded. Every failure was logged as a defect with a screenshot or screen recording.
A23: 4. TEST ENVIRONMENT
A24: Application URL | B24: https://www.saucedemo.com
A25: Browser | B25: Chrome (latest)
A26: Test Data | B26: See the 'Test Data' sheet
A28: 5. ENTRY & EXIT CRITERIA
A29: Entry criteria | B29: • Application URL is accessible • Test cases are written and reviewed • Test accounts and checkout data are available
A30: Exit criteria | B30: • All test cases are executed and a status is recorded • Every failed test case has a logged defect with evidence • Summary metrics are updated
A32: 6. DEFECT SEVERITY & PRIORITY
A33: Severity: Critical | B33: Blocks a core flow and there is no workaround (example: BUG_03 — checkout cannot be completed)
A34: Severity: High | B34: A major function is broken or wrong (example: BUG_02 — item cannot be removed from the cart)
A35: Severity: Medium | B35: A function works partly or has a validation gap; a workaround exists (example: BUG_01, BUG_04, BUG_05, BUG_06)
A36: Severity: Low | B36: Cosmetic or minor issue with no impact on function
A37: Priority: P1 | B37: Fix immediately — blocks testing or release
A38: Priority: P2 | B38: Fix in the current cycle
A39: Priority: P3 | B39: Fix when time permits / next cycle
A41: 7. DELIVERABLES
A42: Workbook | B42: Test Plan, Test Data, Test Cases, Bug Reports, RTM (traceability) and Evidence sheets, plus this Summary
A43: Evidence | B43: Screenshot of every test case in the GitHub folder 'saucedemo-test-cases/screenshots'; screen recordings for bugs on Google Drive (links in Bug Reports)
A44: GitHub | B44: https://github.com/Anushas-hub/manual-testing-portfolio/tree/main/saucedemo-test-cases
A46: 8. ASSUMPTIONS & RISKS
A47: Assumptions | B47: • Sauce Demo has no formal requirements document, so requirements (see RTM sheet) are derived from the observed behaviour of the application. • Results are valid for the application build and Chrome version available on the test date.
A48: Risks | B48: • Sauce Demo is a practice application and intentionally contains defects for some users (for example 'problem_user'). • Testing was done on one browser only.

Sheet Test Data
A1: Test Data
A2: Accounts, checkout inputs and product reference used during execution
A4: A. LOGIN ACCOUNTS (public demo credentials shown on saucedemo.com)
A5: Username | B5: Password | C5: Behaviour | D5: Used In
A6: standard_user | B6: secret_sauce | C6: Normal user, expected to work without issues | D6: TC_01, TC_03, TC_05, TC_09–TC_28, BUG_05, BUG_06
A7: locked_out_user | B7: secret_sauce | C7: Account is locked; login is not allowed | D7: TC_07
A8: problem_user | B8: secret_sauce | C8: Shows deliberate glitches (wrong images, broken cart/sort/checkout) | D8: BUG_01–BUG_04 (exploratory)
A9: performance_glitch_user | B9: secret_sauce | C9: Slow responses | D9: Not used (out of scope)
A10: error_user | B10: secret_sauce | C10: Errors on some actions | D10: Not used (out of scope)
A11: visual_user | B11: secret_sauce | C11: Visual/layout differences | D11: Not used (out of scope)
A13: B. INVALID LOGIN INPUTS
A14: Data Set | B14: Username | C14: Password | D14: Used In
A15: Invalid username | B15: wrong_user | C15: secret_sauce | D15: TC_02
A16: Invalid password | B16: standard_user | C16: wrong_pass | D16: TC_03
A17: Empty username | B17: (blank) | C17: secret_sauce | D17: TC_04
A18: Empty password | B18: standard_user | C18: (blank) | D18: TC_05
A19: Both empty | B19: (blank) | C19: (blank) | D19: TC_06
A21: C. CHECKOUT INFORMATION
A22: Data Set | B22: First Name | C22: Last Name | D22: Zip / Postal Code | E22: Used In
A23: Valid | B23: Anusha | C23: Yadav | D23: 400001 | E23: TC_20
A24: First Name empty | B24: (blank) | C24: Yadav | D24: 400001 | E24: TC_21
A25: Last Name empty | B25: Anusha | C25: (blank) | D25: 400001 | E25: TC_22
A26: Postal Code empty | B26: Anusha | C26: Yadav | D26: (blank) | E26: TC_23
A27: All empty | B27: (blank) | C27: (blank) | D27: (blank) | E27: TC_24
A28: Special characters | B28: 12345!@# | C28: Yadav | D28: 400001 | E28: TC_25, BUG_06
A30: D. PRODUCT CATALOGUE (reference for cart and total checks)
A31: Product | B31: Price (USD)
A32: Sauce Labs Backpack | B32: 29.99
A33: Sauce Labs Bike Light | B33: 9.99
A34: Sauce Labs Bolt T-Shirt | B34: 15.99
A35: Sauce Labs Fleece Jacket | B35: 49.99
A36: Sauce Labs Onesie | B36: 7.99
A37: Test.allTheThings() T-Shirt (Red) | B37: 15.99
A39: Tax rate (observed) | B39: 0.08
A40: Check (TC_26): Backpack tax | B40: =ROUND(B32*B39,2) -> 2.4 | C40: Matches TC_26: Item total $29.99 + Tax $2.40 = Total $32.39. Blue = input values; black = formulas.
A41: Check (TC_26): Total | B41: =B32+B40 -> 32.39

Sheet Test Cases
A1: Test Case ID | B1: Module | C1: Test Scenario | D1: Precondition | E1: Test Steps | F1: Test Data | G1: Expected Result | H1: Actual Result | I1: Status | J1: Priority | K1: Severity | L1: Req ID | M1: Bug ID
A2: TC_01 | B2: Login | C2: Verify login with valid credentials | D2: User is on the Login page (saucedemo.com) | E2: 1. Enter username 'standard_user' 2. Enter password 'secret_sauce' 3. Click Login | F2: standard_user / secret_sauce | G2: User is redirected to the Products page; page title reads 'Products' | H2: User is redirected to the Products page; page title reads 'Products' | I2: Pass | J2: High | K2: N/A | L2: REQ_01 | M2: -
A3: TC_02 | B3: Login | C3: Verify login with invalid username | D3: User is on the Login page | E3: 1. Enter username 'wrong_user' 2. Enter password 'secret_sauce' 3. Click Login | F3: wrong_user / secret_sauce | G3: Error shown: 'Epic sadface: Username and password do not match any user in this service' | H3: Error shown: 'Epic sadface: Username and password do not match any user in this service' | I3: Pass | J3: High | K3: N/A | L3: REQ_02 | M3: -
A4: TC_03 | B4: Login | C4: Verify login with invalid password | D4: User is on the Login page | E4: 1. Enter username 'standard_user' 2. Enter password 'wrong_pass' 3. Click Login | F4: standard_user / wrong_pass | G4: Error shown: 'Epic sadface: Username and password do not match any user in this service' | H4: Error shown: 'Epic sadface: Username and password do not match any user in this service' | I4: Pass | J4: High | K4: N/A | L4: REQ_02 | M4: -
A5: TC_04 | B5: Login | C5: Verify login with empty username field | D5: User is on the Login page | E5: 1. Leave username blank 2. Enter password 'secret_sauce' 3. Click Login | F5: (blank) / secret_sauce | G5: Error shown: 'Epic sadface: Username is required' | H5: Error shown: 'Epic sadface: Username is required' | I5: Pass | J5: Medium | K5: N/A | L5: REQ_03 | M5: -
A6: TC_05 | B6: Login | C6: Verify login with empty password field | D6: User is on the Login page | E6: 1. Enter username 'standard_user' 2. Leave password blank 3. Click Login | F6: standard_user / (blank) | G6: Error shown: 'Epic sadface: Password is required' | H6: Error shown: 'Epic sadface: Password is required' | I6: Pass | J6: Medium | K6: N/A | L6: REQ_03 | M6: -
A7: TC_06 | B7: Login | C7: Verify login with both fields empty | D7: User is on the Login page | E7: 1. Leave username blank 2. Leave password blank 3. Click Login | F7: (blank) / (blank) | G7: Error shown: 'Epic sadface: Username is required' (username validated first) | H7: Error shown: 'Epic sadface: Username is required' (username validated first) | I7: Pass | J7: Low | K7: N/A | L7: REQ_03 | M7: -
A8: TC_07 | B8: Login | C8: Verify login with a locked-out account | D8: User is on the Login page | E8: 1. Enter username 'locked_out_user' 2. Enter password 'secret_sauce' 3. Click Login | F8: locked_out_user / secret_sauce | G8: Error shown: 'Epic sadface: Sorry, this user has been locked out.' | H8: Error shown: 'Epic sadface: Sorry, this user has been locked out.' | I8: Pass | J8: High | K8: N/A | L8: REQ_04 | M8: -
A9: TC_08 | B9: Login | C9: Verify password field masks entered characters | D9: User is on the Login page | E9: 1. Click password field 2. Type any password | F9: secret_sauce | G9: Characters are masked (shown as dots), not visible in plain text | H9: Characters are masked (shown as dots), not visible in plain text | I9: Pass | J9: Low | K9: N/A | L9: REQ_05 | M9: -
A10: TC_09 | B10: Product Listing / Sort | C10: Verify all products display with name, image, price and description | D10: User is logged in as standard_user | E10: 1. Land on the Products page 2. Observe the product grid | F10: N/A | G10: All 6 products (Sauce Labs Backpack, Bike Light, Bolt T-Shirt, Fleece Jacket, Onesie, Test.allTheThings() T-Shirt) display with image, name, description and price | H10: All 6 products are displayed with image, name, description and price | I10: Pass | J10: Medium | K10: N/A | L10: REQ_06 | M10: -
A11: TC_10 | B11: Product Listing / Sort | C11: Verify default sort order on page load | D11: User is logged in as standard_user | E11: 1. Land on the Products page 2. Check the sort dropdown and product order | F11: N/A | G11: Sort dropdown defaults to 'Name (A to Z)' and products are listed alphabetically | H11: Sort dropdown defaults to 'Name (A to Z)' and products are listed alphabetically | I11: Pass | J11: Low | K11: N/A | L11: REQ_07 | M11: -
A12: TC_11 | B12: Product Listing / Sort | C12: Verify sorting by Price (low to high) | D12: User is on the Products page | E12: 1. Open sort dropdown 2. Select 'Price (low to high)' | F12: N/A | G12: Products re-order with the lowest price first, highest price last | H12: Products re-order with the lowest price first, highest price last | I12: Pass | J12: Medium | K12: N/A | L12: REQ_07 | M12: -
... A29: TC_28 | B29: Checkout | C29: Verify 'Cancel' on checkout returns to Products and cart state | D29: User is on the Checkout: Your Information or Overview page | E29: 1. Click 'Cancel' | F29: N/A | G29: User is returned to the Products (or Cart) page | H29: User is returned to the Products (or Cart) page | I29: Pass | J29: Low | K29: N/A | L29: REQ_18 | M29: -

Sheet Bug Reports
A1: Bug ID | B1: Title | C1: Module | D1: Steps to Reproduce | E1: Test Data / Account Used | F1: Expected Result | G1: Actual Result | H1: Severity | I1: Priority | J1: Environment | K1: Screenshot/Screen Recording | L1: Status | M1: Reported By | N1: Date | O1: Related Test Case
A2: BUG_01 | B2: Product images do not match product names | C2: Product Listing / Sort | D2: 1. Log in as 'problem_user' / secret_sauce 2. Open the Products page 3. Compare each product's image to its name/description | E2: problem_user account | F2: Each product image should visually match its name (e.g. 'Sauce Labs Backpack' shows a backpack image) | G2: All product images are incorrect and do not match the product name | H2: Medium | I2: P2 | J2: Chrome (latest), saucedemo.com | K2: View evidence | L2: Confirmed | M2: Anusha Yadav | N2: 46293 | O2: Exploratory (problem_user)
A3: BUG_02 | B3: Cannot remove certain items from the cart once added | C3: Cart | D3: 1. Log in as 'problem_user' / secret_sauce 2. Add 'Sauce Labs Backpack' to the cart 3. Open Cart page 4. Click 'Remove' | E3: problem_user account | F3: Item should be removed from the cart and the cart badge count should decrease | G3: 'Remove' button does not remove the item; item stays in the cart | H3: High | I3: P1 | J3: Chrome (latest), saucedemo.com | K3: View evidence | L3: Confirmed | M3: Anusha Yadav | N3: 46293 | O3: Exploratory (problem_user)
A4: BUG_03 | B4: Last Name field cannot be typed into at checkout, blocking order completion | C4: Checkout | D4: 1. Log in as 'problem_user' / secret_sauce 2. Add any item to cart and proceed to Checkout 3. Try to type into the Last Name field | E4: problem_user account | F4: User should be able to type a last name and complete checkout | G4: Last Name field does not accept keyboard input, so the checkout flow cannot be completed | H4: Critical | I4: P1 | J4: Chrome (latest), saucedemo.com | K4: View evidence | L4: Confirmed | M4: Anusha Yadav | N4: 46293 | O4: Exploratory (problem_user)
A5: BUG_04 | B5: Product sort dropdown has no effect on product order | C5: Product Listing / Sort | D5: 1. Log in as 'problem_user' / secret_sauce 2. Open the Products page 3. Select any option in the sort dropdown | E5: problem_user account | F5: Product list should re-order according to the selected sort option | G5: Product order does not change regardless of the option selected | H5: Medium | I5: P3 | J5: Chrome (latest), saucedemo.com | K5: View evidence | L5: Confirmed | M5: Anusha Yadav | N5: 46293 | O5: Exploratory (problem_user)
A6: BUG_05 | B6: Checkout is allowed with an empty cart (0 items) | C6: Checkout | D6: 1. Log in as 'standard_user' / secret_sauce 2. Remove all items so the cart is empty 3. On the Cart page, click 'Checkout' and enter First Name, Last Name and Postal Code 4. Click 'Continue' 5. Click 'Finish' on the Overview page | E6: standard_user / secret_sauce | F6: Checkout should be blocked when the cart is empty, and a message should be shown to the user | G6: Checkout proceeded with 0 items. Overview page showed Item total $0, Tax $0.00, Total $0.00 with no products listed. Clicking Finish showed 'Thank you for your order!' (checkout-complete.html). No block or warning message was shown. | H6: Medium | I6: P3 | J6: Chrome (latest), saucedemo.com | K6: View evidence | L6: Confirmed | M6: Anusha Yadav | N6: 46293 | O6: TC_19
A7: BUG_06 | B7: Name field accepts numbers and special characters without validation | C7: Checkout | D7: 1. Log in as 'standard_user' / secret_sauce 2. Add an item to the cart 3. Click 'Checkout' 4. Enter '12345!@#' as First Name, 'Yadav' as Last Name and '400001' as Zip on the Your Information page 5. Click 'Continue' 6. Click 'Finish' | E7: standard_user / secret_sauce First Name '12345!@#', Last Name 'Yadav', Zip '400001' | F7: Name field should reject non-alphabetic input and show a validation error | G7: App accepted the input silently; no error message was shown. | H7: Medium | I7: P3 | J7: Chrome (latest), saucedemo.com | K7: View evidence | L7: Confirmed | M7: Anusha Yadav | N7: 46293 | O7: TC_25

Sheet RTM
A1: Requirement Traceability Matrix (RTM)
A2: Requirements are derived from observed application behaviour (Sauce Demo has no formal SRS)
A3: Status reflects the 'standard_user' test cases. Bugs marked 'problem_user' were found by exploratory testing and have no separate test case.
A4: Req ID | B4: Module | C4: Requirement | D4: Test Case IDs | E4: Total TCs | F4: Passed | G4: Failed | H4: Status | I4: Linked Bugs
A5: REQ_01 | B5: Login | C5: User can log in with valid credentials and lands on the Products page | D5: TC_01 | E5: =COUNTIF('Test Cases'!$L$2:$L$500,A5) -> 1 | F5: =COUNTIFS('Test Cases'!$L$2:$L$500,A5,'Test Cases'!$I$2:$I$500,"Pass") -> 1 | G5: =COUNTIFS('Test Cases'!$L$2:$L$500,A5,'Test Cases'!$I$2:$I$500,"Fail") -> 0 | H5: =IF(E5=0,"Not Covered",IF(G5>0,"Fail",IF(F5=E5,"Pass","In Progress"))) -> Pass | I5: -
A6: REQ_02 | B6: Login | C6: Login is rejected with a clear error for an invalid username or password | D6: TC_02 – TC_03 | E6: =COUNTIF('Test Cases'!$L$2:$L$500,A6) -> 2 | F6: =COUNTIFS('Test Cases'!$L$2:$L$500,A6,'Test Cases'!$I$2:$I$500,"Pass") -> 2 | G6: =COUNTIFS('Test Cases'!$L$2:$L$500,A6,'Test Cases'!$I$2:$I$500,"Fail") -> 0 | H6: =IF(E6=0,"Not Covered",IF(G6>0,"Fail",IF(F6=E6,"Pass","In Progress"))) -> Pass | I6: -
A7: REQ_03 | B7: Login | C7: Username and Password are mandatory; a specific error is shown when either is empty | D7: TC_04 – TC_06 | E7: =COUNTIF('Test Cases'!$L$2:$L$500,A7) -> 3 | F7: =COUNTIFS('Test Cases'!$L$2:$L$500,A7,'Test Cases'!$I$2:$I$500,"Pass") -> 3 | G7: =COUNTIFS('Test Cases'!$L$2:$L$500,A7,'Test Cases'!$I$2:$I$500,"Fail") -> 0 | H7: =IF(E7=0,"Not Covered",IF(G7>0,"Fail",IF(F7=E7,"Pass","In Progress"))) -> Pass | I7: -
A8: REQ_04 | B8: Login | C8: A locked-out user cannot log in and sees a lock-out message | D8: TC_07 | E8: =COUNTIF('Test Cases'!$L$2:$L$500,A8) -> 1 | F8: =COUNTIFS('Test Cases'!$L$2:$L$500,A8,'Test Cases'!$I$2:$I$500,"Pass") -> 1 | G8: =COUNTIFS('Test Cases'!$L$2:$L$500,A8,'Test Cases'!$I$2:$I$500,"Fail") -> 0 | H8: =IF(E8=0,"Not Covered",IF(G8>0,"Fail",IF(F8=E8,"Pass","In Progress"))) -> Pass | I8: -
A9: REQ_05 | B9: Login | C9: Password characters are masked while typing | D9: TC_08 | E9: =COUNTIF('Test Cases'!$L$2:$L$500,A9) -> 1 | F9: =COUNTIFS('Test Cases'!$L$2:$L$500,A9,'Test Cases'!$I$2:$I$500,"Pass") -> 1 | G9: =COUNTIFS('Test Cases'!$L$2:$L$500,A9,'Test Cases'!$I$2:$I$500,"Fail") -> 0 | H9: =IF(E9=0,"Not Covered",IF(G9>0,"Fail",IF(F9=E9,"Pass","In Progress"))) -> Pass | I9: -
A10: REQ_06 | B10: Product Listing / Sort | C10: All products display image, name, description and price | D10: TC_09 | E10: =COUNTIF('Test Cases'!$L$2:$L$500,A10) -> 1 | F10: =COUNTIFS('Test Cases'!$L$2:$L$500,A10,'Test Cases'!$I$2:$I$500,"Pass") -> 1 | G10: =COUNTIFS('Test Cases'!$L$2:$L$500,A10,'Test Cases'!$I$2:$I$500,"Fail") -> 0 | H10: =IF(E10=0,"Not Covered",IF(G10>0,"Fail",IF(F10=E10,"Pass","In Progress"))) -> Pass | I10: BUG_01 (problem_user, exploratory)
A11: REQ_07 | B11: Product Listing / Sort | C11: Products can be sorted by name and price (default: Name A to Z) | D11: TC_10 – TC_13 | E11: =COUNTIF('Test Cases'!$L$2:$L$500,A11) -> 4 | F11: =COUNTIFS('Test Cases'!$L$2:$L$500,A11,'Test Cases'!$I$2:$I$500,"Pass") -> 4 | G11: =COUNTIFS('Test Cases'!$L$2:$L$500,A11,'Test Cases'!$I$2:$I$500,"Fail") -> 0 | H11: =IF(E11=0,"Not Covered",IF(G11>0,"Fail",IF(F11=E11,"Pass","In Progress"))) -> Pass | I11: BUG_04 (problem_user, exploratory)
A12: REQ_08 | B12: Cart | C12: Adding products updates the cart badge and the button label | D12: TC_14 – TC_15 | E12: =COUNTIF('Test Cases'!$L$2:$L$500,A12) -> 2 | F12: =COUNTIFS('Test Cases'!$L$2:$L$500,A12,'Test Cases'!$I$2:$I$500,"Pass") -> 2 | G12: =COUNTIFS('Test Cases'!$L$2:$L$500,A12,'Test Cases'!$I$2:$I$500,"Fail") -> 0 | H12: =IF(E12=0,"Not Covered",IF(G12>0,"Fail",IF(F12=E12,"Pass","In Progress"))) -> Pass | I12: -
A13: REQ_09 | B13: Cart | C13: User can remove an item from the cart | D13: TC_16 | E13: =COUNTIF('Test Cases'!$L$2:$L$500,A13) -> 1 | F13: =COUNTIFS('Test Cases'!$L$2:$L$500,A13,'Test Cases'!$I$2:$I$500,"Pass") -> 1 | G13: =COUNTIFS('Test Cases'!$L$2:$L$500,A13,'Test Cases'!$I$2:$I$500,"Fail") -> 0 | H13: =IF(E13=0,"Not Covered",IF(G13>0,"Fail",IF(F13=E13,"Pass","In Progress"))) -> Pass | I13: BUG_02 (problem_user, exploratory)
A14: REQ_10 | B14: Cart | C14: Cart contents persist when navigating between pages | D14: TC_17 | E14: =COUNTIF('Test Cases'!$L$2:$L$500,A14) -> 1 | F14: =COUNTIFS('Test Cases'!$L$2:$L$500,A14,'Test Cases'!$I$2:$I$500,"Pass") -> 1 | G14: =COUNTIFS('Test Cases'!$L$2:$L$500,A14,'Test Cases'!$I$2:$I$500,"Fail") -> 0 | H14: =IF(E14=0,"Not Covered",IF(G14>0,"Fail",IF(F14=E14,"Pass","In Progress"))) -> Pass | I14: -
A15: REQ_11 | B15: Cart | C15: 'Continue Shopping' returns the user to the Products page | D15: TC_18 | E15: =COUNTIF('Test Cases'!$L$2:$L$500,A15) -> 1 | F15: =COUNTIFS('Test Cases'!$L$2:$L$500,A15,'Test Cases'!$I$2:$I$500,"Pass") -> 1 | G15: =COUNTIFS('Test Cases'!$L$2:$L$500,A15,'Test Cases'!$I$2:$I$500,"Fail") -> 0 | H15: =IF(E15=0,"Not Covered",IF(G15>0,"Fail",IF(F15=E15,"Pass","In Progress"))) -> Pass | I15: -
A16: REQ_12 | B16: Cart | C16: Checkout is not allowed with an empty cart | D16: TC_19 | E16: =COUNTIF('Test Cases'!$L$2:$L$500,A16) -> 1 | F16: =COUNTIFS('Test Cases'!$L$2:$L$500,A16,'Test Cases'!$I$2:$I$500,"Pass") -> 0 | G16: =COUNTIFS('Test Cases'!$L$2:$L$500,A16,'Test Cases'!$I$2:$I$500,"Fail") -> 1 | H16: =IF(E16=0,"Not Covered",IF(G16>0,"Fail",IF(F16=E16,"Pass","In Progress"))) -> Fail | I16: BUG_05
... A22: REQ_18 | B22: Checkout | C22: User can cancel checkout and return to the previous page | D22: TC_28 | E22: =COUNTIF('Test Cases'!$L$2:$L$500,A22) -> 1 | F22: =COUNTIFS('Test Cases'!$L$2:$L$500,A22,'Test Cases'!$I$2:$I$500,"Pass") -> 1 | G22: =COUNTIFS('Test Cases'!$L$2:$L$500,A22,'Test Cases'!$I$2:$I$500,"Fail") -> 0 | H22: =IF(E22=0,"Not Covered",IF(G22>0,"Fail",IF(F22=E22,"Pass","In Progress"))) -> Pass | I22: -
D23: Total | E23: =SUM(E5:E22) -> 28 | F23: =SUM(F5:F22) -> 26 | G23: =SUM(G5:G22) -> 2

Sheet Summary
A1: SauceDemo E-Commerce — Test Summary Report
A2: Manual Functional Testing (Black-box) | saucedemo.com
A4: PROJECT INFORMATION
A5: Application Under Test | B5: Sauce Demo (https://www.saucedemo.com)
A6: Tested By | B6: Anusha Yadav
A7: Test Type | B7: Manual Functional (Black-box)
A8: Browser | B8: Chrome (latest)
A9: Test Date | B9: 46293
A10: GitHub Repository | B10: https://github.com/Anushas-hub/manual-testing-portfolio/tree/main/saucedemo-test-cases
A12: TEST EXECUTION SUMMARY
A13: Total Test Cases | B13: =COUNTA('Test Cases'!$A$2:$A$500) -> 28
A14: Passed | B14: =COUNTIF('Test Cases'!$I$2:$I$500,"Pass") -> 26
A15: Failed | B15: =COUNTIF('Test Cases'!$I$2:$I$500,"Fail") -> 2
A16: Not Executed | B16: =B13-B14-B15 -> 0
A17: Pass % (of executed) | B17: =IFERROR(B14/(B14+B15),0) -> 0.92857143
A18: Execution % (of total) | B18: =IFERROR((B14+B15)/B13,0) -> 1
A19: Screenshots Uploaded to GitHub | B19: =COUNTIF('[1]#REF'!$F$4:$F$31,"Yes")&" / "&COUNTA('[1]#REF'!$A$4:$A$31) -> #VALUE!
A21: MODULE-WISE RESULTS
A22: Module | B22: Total | C22: Passed | D22: Failed | E22: Pass %
A23: Login | B23: =COUNTIF('Test Cases'!$B$2:$B$500,A23) -> 8 | C23: =COUNTIFS('Test Cases'!$B$2:$B$500,A23,'Test Cases'!$I$2:$I$500,"Pass") -> 8 | D23: =COUNTIFS('Test Cases'!$B$2:$B$500,A23,'Test Cases'!$I$2:$I$500,"Fail") -> 0 | E23: =IFERROR(C23/(C23+D23),0) -> 1
A24: Product Listing / Sort | B24: =COUNTIF('Test Cases'!$B$2:$B$500,A24) -> 5 | C24: =COUNTIFS('Test Cases'!$B$2:$B$500,A24,'Test Cases'!$I$2:$I$500,"Pass") -> 5 | D24: =COUNTIFS('Test Cases'!$B$2:$B$500,A24,'Test Cases'!$I$2:$I$500,"Fail") -> 0 | E24: =IFERROR(C24/(C24+D24),0) -> 1
A25: Cart | B25: =COUNTIF('Test Cases'!$B$2:$B$500,A25) -> 6 | C25: =COUNTIFS('Test Cases'!$B$2:$B$500,A25,'Test Cases'!$I$2:$I$500,"Pass") -> 5 | D25: =COUNTIFS('Test Cases'!$B$2:$B$500,A25,'Test Cases'!$I$2:$I$500,"Fail") -> 1 | E25: =IFERROR(C25/(C25+D25),0) -> 0.83333333
A26: Checkout | B26: =COUNTIF('Test Cases'!$B$2:$B$500,A26) -> 9 | C26: =COUNTIFS('Test Cases'!$B$2:$B$500,A26,'Test Cases'!$I$2:$I$500,"Pass") -> 8 | D26: =COUNTIFS('Test Cases'!$B$2:$B$500,A26,'Test Cases'!$I$2:$I$500,"Fail") -> 1 | E26: =IFERROR(C26/(C26+D26),0) -> 0.88888889
A27: Total | B27: =SUM(B23:B26) -> 28 | C27: =SUM(C23:C26) -> 26 | D27: =SUM(D23:D26) -> 2 | E27: =IFERROR(C27/(C27+D27),0) -> 0.92857143
A29: DEFECT SUMMARY
A30: Total Bugs Logged | B30: =COUNTA('Bug Reports'!$A$2:$A$500) -> 6
A31: By Severity | B31: Count
A32: Critical | B32: =COUNTIF('Bug Reports'!$H$2:$H$500,A32) -> 1
A33: High | B33: =COUNTIF('Bug Reports'!$H$2:$H$500,A33) -> 1
A34: Medium | B34: =COUNTIF('Bug Reports'!$H$2:$H$500,A34) -> 4
A35: Low | B35: =COUNTIF('Bug Reports'!$H$2:$H$500,A35) -> 0
A37: By Priority | B37: Count
A38: P1 | B38: =COUNTIF('Bug Reports'!$I$2:$I$500,A38) -> 2
A39: P2 | B39: =COUNTIF('Bug Reports'!$I$2:$I$500,A39) -> 1
A40: P3 | B40: =COUNTIF('Bug Reports'!$I$2:$I$500,A40) -> 3
A42: By Module | B42: Count
A43: Login | B43: =COUNTIF('Bug Reports'!$C$2:$C$500,A43) -> 0
A44: Product Listing / Sort | B44: =COUNTIF('Bug Reports'!$C$2:$C$500,A44) -> 2
A45: Cart | B45: =COUNTIF('Bug Reports'!$C$2:$C$500,A45) -> 1
A46: Checkout | B46: =COUNTIF('Bug Reports'!$C$2:$C$500,A46) -> 3
...
